Workbook

Sheet Summary
A1: DIGITAL LENDING CREDIT SCORECARD — BENCHMARKED TO BAJAJ FINANCE
A2: Fintech Finance portfolio project — illustrative framework, calibrated to a real lender's disclosed asset quality
A3: Company benchmark: Bajaj Finance Limited, Q1 FY2027 (quarter ended June 30, 2026)
A5: Metric | B5: This Framework | C5: Bajaj Finance Actual
A6: Approval Rate | B6: ='Portfolio Simulation'!B13 -> 0.98
A7: Blended Portfolio PD / Credit Cost | B7: ='Portfolio Simulation'!B14 -> 0.01355102 | C7: ='Company Context'!B15 -> 0.0131
A8: Blended Portfolio Yield | B8: ='Portfolio Simulation'!B17 -> 0.1677551
A9: Blended Contribution Margin (% of ticket) | B9: ='Unit Economics'!B16 -> 0.031204082
A11: Contribution per Average Loan, by Tier
A12: A (Prime) | B12: ='Unit Economics'!F11 -> 600
A13: B (Near-Prime) | B13: ='Unit Economics'!F12 -> 4200
A14: C (Subprime) | B14: ='Unit Economics'!F13 -> 9300
A15: D (High-Risk) | B15: ='Unit Economics'!F14 -> 13050
A29: Key Takeaways
A30: The framework's blended portfolio default rate (1.36%) lands close to Bajaj Finance's real disclosed credit cost (1.31%, ex management overlay) — a deliberate calibration check, not a coincidence, and the strongest evidence this illustrative scorecard is directionally realistic rather than arbitrary. The more interesting finding sits in the Unit Economics tab: higher-risk tiers (C, D) generate MORE contribution margin per loan than the Prime tier, because risk-based pricing more than compensates for expected losses in an expected-value sense. Prime's real advantage is lower variance and volume stability, not per-loan profitability — exactly why a real lender still wants a prime-heavy book despite thinner unit margins there: a macro shock hits the subprime/high-risk tiers hardest, which is the same logic behind Bajaj Finance's own precautionary management overlay this quarter.

Sheet Company Context
A1: BAJAJ FINANCE LIMITED — REAL DISCLOSED METRICS (BENCHMARK / VALIDATION LAYER)
A2: Q1 FY2027 (quarter ended June 30, 2026) results, as reported. India's largest NBFC by AUM. Used in this project to calibrate and sanity-check the illustrative scorecard framework on the Portfolio Simulation tab.
A4: Metric | B4: Q1 FY27A | C4: Q1 FY26A (yr-ago)
A5: Assets Under Management (₹ crore) | B5: 546944 | C5: 441000
A6: AUM Growth % YoY | B6: 0.239
A7: New Loans Booked (million, in qtr) | B7: 16.13 | C7: 13.49
A8: New Customers Added (million, in qtr) | B8: 5 | C8: n/a
A9: Consolidated Net Profit (₹ crore) | B9: 5986 | C9: 4700
A10: Net Interest Income (₹ crore) | B10: 12571 | C10: 10228
A11: Net Total Income (₹ crore) | B11: 15224 | C11: n/a
A12: Gross NPA % | B12: 0.0096 | C12: 0.0103
A13: Net NPA % | B13: 0.0039 | C13: 0.005
A14: Provisioning Coverage (Stage 3) | B14: 0.6 | C14: n/a
A15: Loan Loss / Avg. AUM (ex management overlay) | B15: 0.0131
A16: ROE (annualized) | B16: 0.204 | C16: n/a
A17: Capital Adequacy Ratio (CRAR) | B17: 0.209 | C17: n/a
A18: Opex / Net Total Income | B18: 0.334 | C18: 0.331
A20: Long-Term Guidance (per company investor presentation)
A21: AUM Growth | B21: 23-25%
A22: GNPA Ceiling | B22: <1.4%
A23: ROA Target | B23: 4.3-4.7%
A24: ROE Target | B24: 19-21%
A26: Digital / AI Context
A27: Management is scaling its “FinAI” initiative — expanding the AI team from 230 to 400 people, plus 300 more in digital platforms — with the explicit goal of keeping AI costs below the cost of equivalent human labor, and targeting 25-40bps of opex-ratio improvement in FY2027 from AI-driven efficiency. This is the real backdrop this project's illustrative scorecard is modeling a simplified version of.

Sheet Scorecard Framework
A1: ILLUSTRATIVE CREDIT SCORECARD — 8-FACTOR POINTS-BASED FRAMEWORK
A2: This is an illustrative framework built for this project, not Bajaj Finance's actual proprietary scorecard (which is confidential). Factor selection and weights reflect standard NBFC/fintech underwriting practice; the model is calibrated against Bajaj Finance's real disclosed portfolio-level asset quality on the Portfolio Simulation tab.
A4: 1. Net Monthly Income (₹)
A5: < 25,000 | B5: 0
A6: 25,000 – 50,000 | B6: 10
A7: 50,000 – 100,000 | B7: 20
A8: 100,000 – 200,000 | B8: 30
A9: > 200,000 | B9: 40
A11: 2. Debt-to-Income Ratio (existing EMI/income)
A12: > 50% | B12: 0
A13: 35–50% | B13: 10
A14: 20–35% | B14: 20
A15: < 20% | B15: 30
A17: 3. Bureau Score (CIBIL-style, 300–900)
A18: < 650 | B18: 0
A19: 650–700 | B19: 15
A20: 700–750 | B20: 30
A21: 750–800 | B21: 45
A22: > 800 | B22: 60
A24: 4. Employment Type
A25: Self-employed, informal/no ITR | B25: 0
A26: Self-employed professional | B26: 15
A27: Salaried, private sector | B27: 20
A28: Salaried, government/PSU | B28: 30
A30: 5. Employment / Business Vintage
A31: < 1 year | B31: 0
A32: 1–3 years | B32: 10
A33: 3–5 years | B33: 20
A34: > 5 years | B34: 30
A36: 6. Existing Relationship with Lender
A37: New-to-credit (no bureau history) | B37: 0
A38: New-to-lender, has bureau history | B38: 10
A39: Existing customer, <2 yrs, good standing | B39: 20
A40: Existing customer, >2 yrs, good standing | B40: 35
A42: 7. Loan-to-Income Ratio (loan amount / annual income)
A43: > 5x | B43: 0
A44: 3–5x | B44: 10
A45: 1.5–3x | B45: 20
A46: < 1.5x | B46: 30
A48: 8. Digital Footprint / Alternative Data Score
...

Sheet Portfolio Simulation
A1: SYNTHETIC APPLICANT POOL — SIMULATION & CALIBRATION AGAINST REAL BFL METRICS
A2: 10,000 illustrative applicants distributed across tiers, calibrated so the blended portfolio default rate lands close to Bajaj Finance's real disclosed credit cost (validation, not a coincidence to hide).
A4: Tier | B4: Applicant Share | C4: # Applicants (of 10,000) | D4: Assumed PD | E4: Assumed Rate | F4: Expected Defaults | G4: Book Share (of approved)
A5: A (Prime) | B5: 0.3 | C5: =B5*10000 -> 3000 | D5: 0.003 | E5: 0.13 | F5: =C5*D5 -> 9 | G5: =C5/SUM($C$5:$C$8) -> 0.30612245
A6: B (Near-Prime) | B6: 0.42 | C6: =B6*10000 -> 4200 | D6: 0.009 | E6: 0.16 | F6: =C6*D6 -> 37.8 | G6: =C6/SUM($C$5:$C$8) -> 0.42857143
A7: C (Subprime) | B7: 0.2 | C7: =B7*10000 -> 2000 | D7: 0.025 | E7: 0.21 | F7: =C7*D7 -> 50 | G7: =C7/SUM($C$5:$C$8) -> 0.20408163
A8: D (High-Risk) | B8: 0.06 | C8: =B8*10000 -> 600 | D8: 0.06 | E8: 0.27 | F8: =C8*D8 -> 36 | G8: =C8/SUM($C$5:$C$8) -> 0.06122449
A9: Reject | B9: 0.02 | C9: =B9*10000 -> 200
A10: Total | B10: =SUM(B5:B9) -> 1 | C10: =SUM(C5:C9) -> 10000
A12: Portfolio-Level Output
A13: Approval Rate | B13: =SUM(C5:C8)/C10 -> 0.98
A14: Blended Portfolio PD (approved book) | B14: =SUM(F5:F8)/SUM(C5:C8) -> 0.01355102
A15: vs. Bajaj Finance actual (ex-overlay) | B15: ='Company Context'!B15 -> 0.0131
A16: Gap | B16: =B14-B15 -> 0.00045102041
A17: Blended Portfolio Yield | B17: =SUMPRODUCT(C5:C8,E5:E8)/SUM(C5:C8) -> 0.1677551

Sheet Unit Economics
A1: PER-LOAN UNIT ECONOMICS BY RISK TIER
A2: Illustrative average ticket size and cost-of-funds assumption, applied to the scorecard's tier structure. Opex ratio anchored to Bajaj Finance's real disclosed 33.4% opex/net-total-income.
A4: Assumption | B4: Value
A5: Average Ticket Size (₹) | B5: 150000
A6: Cost of Funds | B6: 0.078
A7: Opex % of AUM (approx., derived) | B7: 0.045
A9: Contribution Margin by Tier (per average ₹150,000 loan)
A10: Tier | B10: Interest Income | C10: Funding Cost | D10: Opex | E10: Credit Cost | F10: Contribution
A11: A (Prime) | B11: =$B$5*'Portfolio Simulation'!E5 -> 19500 | C11: =$B$5*$B$6 -> 11700 | D11: =$B$5*$B$7 -> 6750 | E11: =$B$5*'Portfolio Simulation'!D5 -> 450 | F11: =B11-C11-D11-E11 -> 600
A12: B (Near-Prime) | B12: =$B$5*'Portfolio Simulation'!E6 -> 24000 | C12: =$B$5*$B$6 -> 11700 | D12: =$B$5*$B$7 -> 6750 | E12: =$B$5*'Portfolio Simulation'!D6 -> 1350 | F12: =B12-C12-D12-E12 -> 4200
A13: C (Subprime) | B13: =$B$5*'Portfolio Simulation'!E7 -> 31500 | C13: =$B$5*$B$6 -> 11700 | D13: =$B$5*$B$7 -> 6750 | E13: =$B$5*'Portfolio Simulation'!D7 -> 3750 | F13: =B13-C13-D13-E13 -> 9300
A14: D (High-Risk) | B14: =$B$5*'Portfolio Simulation'!E8 -> 40500 | C14: =$B$5*$B$6 -> 11700 | D14: =$B$5*$B$7 -> 6750 | E14: =$B$5*'Portfolio Simulation'!D8 -> 9000 | F14: =B14-C14-D14-E14 -> 13050
A15: Blended (portfolio-weighted) | B15: =$B$5*'Portfolio Simulation'!B17 -> 25163.265 | C15: =$B$5*$B$6 -> 11700 | D15: =$B$5*$B$7 -> 6750 | E15: =$B$5*'Portfolio Simulation'!B14 -> 2032.6531 | F15: =B15-C15-D15-E15 -> 4680.6122
A16: as % of ticket size | B16: =F15/$B$5 -> 0.031204082
A17: vs. BFL guided ROA (4.3-4.7%)
