Workbook

Sheet Summary
A1: THE COCA-COLA COMPANY (NYSE: KO) — DCF + COMPARABLE COMPANY VALUATION
A2: Proof-of-work project — Private Equity / Equity Research portfolio
A3: All figures in USD millions unless noted. Prepared using FY2021-FY2025 10-K data and market data as of Aug 21, 2026.
A5: Current Share Price | B5: 91.1
A6: 52-Week Range | B6: $65.35 - $91.86
A7: Shares Outstanding (mm) | B7: 4301.6
A8: Market Capitalization | B8: =B5*B7 -> 391875.76
A10: Valuation Method | B10: Implied Value/Share | C10: Implied Upside/(Downside)
A11: DCF (Base Case) | B11: ='DCF Model'!B46 -> 61.892424 | C11: =B11/$B$5-1 -> -0.32061006
A12: Comps — P/E Implied | B12: =Comps!C19 -> 101.676 | C12: =B12/$B$5-1 -> 0.11609221
A13: Comps — EV/EBITDA Implied | B13: =Comps!C20 -> 39.965621 | C13: =B13/$B$5-1 -> -0.56129944
A15: Blended Fair Value (avg. of 3 methods) | B15: =AVERAGE(B11:B13) -> 67.844682 | C15: =B15/$B$5-1 -> -0.25527243
A18: Recommendation
A19: KO trades near its 52-week high following a strong Q2 2026 beat (organic revenue +6%, margin expansion of ~90-120bps) and raised full-year guidance. The DCF and comps methods below should be read together with the sensitivity table on the DCF Model tab, since the conclusion is meaningfully sensitive to WACC and terminal growth assumptions. See the accompanying write-up for the full investment view.
A25: How to read this workbook
A26: Blue text | B26: Hardcoded input or assumption — safe to edit
A27: Black text | B27: Formula — do not overwrite
A28: Green text | B28: Link pulling from another tab
A29: Yellow fill | B29: Key scenario lever — see DCF Model!B3 to flex Bear/Base/Bull
A31: Tab guide
A32: Summary | B32: This page — headline output and recommendation.
A33: Historicals | B33: FY2021-FY2025 financials sourced from 10-K filings, plus TTM figures.
A34: DCF Model | B34: WACC build, 5-yr unlevered FCF, terminal value, and WACC/growth sensitivity.
A35: Scenarios | B35: Bear/Base/Bull assumption sets that drive the DCF Model tab.
A36: Comps | B36: Peer trading multiples (PepsiCo, KDP, Monster) and implied KO valuation.
A38: Football Field — Implied Value per Share
A39: Method | B39: Low | C39: High | D39: Span
A40: DCF (Sensitivity Range) | B40: =MIN('DCF Model'!B50:F54) -> 41.412803 | C40: =MAX('DCF Model'!B50:F54) -> 117.30965 | D40: =C40-B40 -> 75.896851
A41: Comps — P/E Range | B41: =MIN(Comps!F5:F7)*Comps!B13 -> 74.592 | C41: =MAX(Comps!F5:F7)*Comps!B13 -> 139.86 | D41: =C41-B41 -> 65.268
A42: Comps — EV/EBITDA Range | B42: =(MIN(Comps!G5:G6)*Comps!B14-Comps!B15)/Comps!B16 -> 38.964992 | C42: =(MAX(Comps!G5:G6)*Comps!B14-Comps!B15)/Comps!B16 -> 40.96625 | D42: =C42-B42 -> 2.0012583
A43: Current Price (marker) | B43: =B5-1 -> 90.1 | C43: =B5+1 -> 92.1 | D43: =C43-B43 -> 2

Sheet Historicals
A1: THE COCA-COLA COMPANY — HISTORICAL FINANCIALS (FY2021-FY2025)
A2: Source: Company 10-K filings (FY2021-FY2025); stockanalysis.com aggregation. $ in millions except per-share data.
A4: Fiscal Year | B4: 2021 | C4: 2022 | D4: 2023 | E4: 2024 | F4: 2025
A5: Net Operating Revenue | B5: 38655 | C5: 43004 | D5: 45754 | E5: 47061 | F5: 47941
A6: Revenue Growth % | B6: n/a | C6: =C5/B5-1 -> 0.11250808 | D6: =D5/C5-1 -> 0.06394754 | E6: =E5/D5-1 -> 0.028565808 | F6: =F5/E5-1 -> 0.018699135
A7: Gross Profit | B7: 23298 | C7: 25004 | D7: 27234 | E7: 28737 | F7: 29544
A8: Gross Margin % | B8: =B7/B5 -> 0.60271634 | C8: =C7/C5 -> 0.58143429 | D8: =D7/D5 -> 0.59522665 | E8: =E7/E5 -> 0.61063301 | F8: =F7/F5 -> 0.61625748
A9: Operating Income | B9: 11433 | C9: 12341 | D9: 13246 | E9: 14292 | F9: 15028
A10: Operating Margin % | B10: =B9/B5 -> 0.29577028 | C10: =C9/C5 -> 0.2869733 | D10: =D9/D5 -> 0.28950474 | E10: =E9/E5 -> 0.30369095 | F10: =F9/F5 -> 0.31346864
A11: Net Income (attrib. to Shareowners) | B11: 9771 | C11: 9542 | D11: 10714 | E11: 10631 | F11: 13107
A12: Net Margin % | B12: =B11/B5 -> 0.25277454 | C12: =C11/C5 -> 0.22188634 | D12: =D11/D5 -> 0.23416532 | E12: =E11/E5 -> 0.2258983 | F12: =F11/F5 -> 0.27339855
A13: Diluted EPS ($) | B13: 2.25 | C13: 2.19 | D13: 2.47 | E13: 2.46 | F13: 3.04
A15: Cash Flow
A16: Cash Flow from Operations | B16: 12625 | C16: 11018 | D16: 11599 | E16: 6805 | F16: 7408
A17: Capital Expenditures | B17: 1367 | C17: 1484 | D17: 1852 | E17: 2064 | F17: 2112
A18: Free Cash Flow (OCF - Capex) | B18: =B16-B17 -> 11258 | C18: =C16-C17 -> 9534 | D18: =D16-D17 -> 9747 | E18: =E16-E17 -> 4741 | F18: =F16-F17 -> 5296
A20: Balance Sheet (selected)
A21: Cash & Short-Term Investments | B21: 12626 | C21: 11631 | D21: 13663 | E21: 14571 | F21: 15806
A22: Total Debt | B22: 44246 | C22: 42279 | D22: 44539 | E22: 46657 | F22: 47914
A23: Net Debt | B23: =B22-B21 -> 31620 | C23: =C22-C21 -> 30648 | D23: =D22-D21 -> 30876 | E23: =E22-E21 -> 32086 | F23: =F22-F21 -> 32108
A25: Dividend per Share ($) | B25: 1.68 | C25: 1.76 | D25: 1.84 | E25: 1.94 | F25: 2.04
A28: TTM (period ended Jul 3, 2026)
A29: TTM Revenue | B29: 50129
A30: TTM Operating Income | B30: 15964
A31: TTM Net Income | B31: 14316
A32: TTM Diluted EPS ($) | B32: 3.33
A33: Est. D&A (assumption, ~2.5% of revenue) | B33: =B29*0.025 -> 1253.225
A34: TTM EBITDA (Op. Income + Est. D&A) | B34: =B30+B33 -> 17217.225

Sheet DCF Model
A1: THE COCA-COLA COMPANY — DISCOUNTED CASH FLOW MODEL
A2: $ in millions except per-share data. Explicit forecast FY2026E-FY2030E; Gordon Growth terminal value.
A3: Scenario (Bear / Base / Bull) | B3: Base
A4: WACC Calculation
A5: Risk-Free Rate (10Y UST) | B5: 0.043
A6: Equity Risk Premium | B6: 0.05
A7: Beta (Levered) | B7: 0.6
A8: Cost of Equity | B8: =B5+B7*B6 -> 0.073
A9: Pre-Tax Cost of Debt | B9: 0.038
A10: Tax Rate | B10: 0.209
A11: After-Tax Cost of Debt | B11: =B9*(1-B10) -> 0.030058
A12: Market Value of Equity | B12: =Summary!B8 -> 391875.76
A13: Market Value of Debt (book value proxy) | B13: =Historicals!F22 -> 47914
A14: Weight of Equity | B14: =B12/(B12+B13) -> 0.89105249
A15: Weight of Debt | B15: =B13/(B12+B13) -> 0.10894751
A16: WACC | B16: =B14*B8+B15*B11 -> 0.068321576
A18: Revenue & FCF Build
A19: Fiscal Year | B19: 2025A | C19: 2026E | D19: 2027E | E19: 2028E | F19: 2029E | G19: 2030E
A20: Revenue Growth % | C20: =INDEX(Scenarios!$B$6:$B$8,MATCH($B$3,Scenarios!$A$6:$A$8,0)) -> 0.05 | D20: =INDEX(Scenarios!$C$6:$C$8,MATCH($B$3,Scenarios!$A$6:$A$8,0)) -> 0.048 | E20: =INDEX(Scenarios!$D$6:$D$8,MATCH($B$3,Scenarios!$A$6:$A$8,0)) -> 0.045 | F20: =INDEX(Scenarios!$E$6:$E$8,MATCH($B$3,Scenarios!$A$6:$A$8,0)) -> 0.042 | G20: =INDEX(Scenarios!$F$6:$F$8,MATCH($B$3,Scenarios!$A$6:$A$8,0)) -> 0.04
A21: Revenue | B21: =Historicals!F5 -> 47941 | C21: =B21*(1+C20) -> 50338.05 | D21: =C21*(1+D20) -> 52754.276 | E21: =D21*(1+E20) -> 55128.219 | F21: =E21*(1+F20) -> 57443.604 | G21: =F21*(1+G20) -> 59741.348
A22: EBIT Margin % | C22: =INDEX(Scenarios!$B$12:$B$14,MATCH($B$3,Scenarios!$A$6:$A$8,0)) -> 0.318 | D22: =INDEX(Scenarios!$C$12:$C$14,MATCH($B$3,Scenarios!$A$6:$A$8,0)) -> 0.322 | E22: =INDEX(Scenarios!$D$12:$D$14,MATCH($B$3,Scenarios!$A$6:$A$8,0)) -> 0.326 | F22: =INDEX(Scenarios!$E$12:$E$14,MATCH($B$3,Scenarios!$A$6:$A$8,0)) -> 0.33 | G22: =INDEX(Scenarios!$F$12:$F$14,MATCH($B$3,Scenarios!$A$6:$A$8,0)) -> 0.333
A23: EBIT | B23: =Historicals!F9 -> 15028 | C23: =C21*C22 -> 16007.5 | D23: =D21*D22 -> 16986.877 | E23: =E21*E22 -> 17971.799 | F23: =F21*F22 -> 18956.389 | G23: =G21*G22 -> 19893.869
A24: Tax Rate % | C24: =$B$10 -> 0.209 | D24: =$B$10 -> 0.209 | E24: =$B$10 -> 0.209 | F24: =$B$10 -> 0.209 | G24: =$B$10 -> 0.209
A25: NOPAT | C25: =C23*(1-C24) -> 12661.932 | D25: =D23*(1-D24) -> 13436.62 | E25: =E23*(1-E24) -> 14215.693 | F25: =F23*(1-F24) -> 14994.504 | G25: =G23*(1-G24) -> 15736.05
A26: (+) D&A (% of revenue) | C26: =C21*0.025 -> 1258.4513 | D26: =D21*0.025 -> 1318.8569 | E26: =E21*0.025 -> 1378.2055 | F26: =F21*0.025 -> 1436.0901 | G26: =G21*0.025 -> 1493.5337
A27: (-) Capital Expenditures (% of revenue) | C27: =C21*0.044 -> 2214.8742 | D27: =D21*0.044 -> 2321.1882 | E27: =E21*0.044 -> 2425.6416 | F27: =F21*0.044 -> 2527.5186 | G27: =G21*0.044 -> 2628.6193
A28: (-) Increase in Net Working Capital | C28: =C21*0.003 -> 151.01415 | D28: =D21*0.003 -> 158.26283 | E28: =E21*0.003 -> 165.38466 | F28: =F21*0.003 -> 172.33081 | G28: =G21*0.003 -> 179.22404
A29: Unlevered Free Cash Flow | C29: =C25+C26-C27-C28 -> 11554.495 | D29: =D25+D26-D27-D28 -> 12276.026 | E29: =E25+E26-E27-E28 -> 13002.872 | F29: =F25+F26-F27-F28 -> 13730.745 | G29: =G25+G26-G27-G28 -> 14421.741
A30: Discount Period | C30: 1 | D30: 2 | E30: 3 | F30: 4 | G30: 5
A31: Discount Factor | C31: =1/(1+$B$16)^C30 -> 0.93604774 | D31: =1/(1+$B$16)^D30 -> 0.87618538 | E31: =1/(1+$B$16)^E30 -> 0.82015134 | F31: =1/(1+$B$16)^F30 -> 0.76770082 | G31: =1/(1+$B$16)^G30 -> 0.71860462
A32: PV of Unlevered FCF | C32: =C29*C31 -> 10815.559 | D32: =D29*D31 -> 10756.074 | E32: =E29*E31 -> 10664.323 | F32: =F29*F31 -> 10541.104 | G32: =G29*G31 -> 10363.529
A34: Terminal Value
A35: Terminal Growth Rate | B35: 0.025
A36: Terminal Value (Gordon Growth, undiscounted) | B36: =G29*(1+B35)/(B16-B35) -> 341222.22
A37: PV of Terminal Value | B37: =B36*G31 -> 245203.86
A39: Valuation Bridge
A40: Sum of PV of Explicit FCF | B40: =SUM(C32:G32) -> 53140.59
A41: (+) PV of Terminal Value | B41: =B37 -> 245203.86
A42: Enterprise Value | B42: =B40+B37 -> 298344.45
A43: (-) Net Debt | B43: =Historicals!F23 -> 32108
...

Sheet Scenarios
A1: THE COCA-COLA COMPANY — SCENARIO ASSUMPTIONS
A2: Bear / Base / Bull assumptions driving the DCF Model tab. Change the Scenario cell on the DCF Model tab to flex the model between cases.
A4: Revenue Growth % by Scenario
A5: Scenario | B5: 2026E | C5: 2027E | D5: 2028E | E5: 2029E | F5: 2030E
A6: Bear | B6: 0.02 | C6: 0.02 | D6: 0.018 | E6: 0.018 | F6: 0.015
A7: Base | B7: 0.05 | C7: 0.048 | D7: 0.045 | E7: 0.042 | F7: 0.04
A8: Bull | B8: 0.07 | C8: 0.065 | D8: 0.06 | E8: 0.055 | F8: 0.05
A10: EBIT Margin % by Scenario
A11: Scenario | B11: 2026E | C11: 2027E | D11: 2028E | E11: 2029E | F11: 2030E
A12: Bear | B12: 0.305 | C12: 0.303 | D12: 0.3 | E12: 0.298 | F12: 0.295
A13: Base | B13: 0.318 | C13: 0.322 | D13: 0.326 | E13: 0.33 | F13: 0.333
A14: Bull | B14: 0.325 | C14: 0.335 | D14: 0.345 | E14: 0.355 | F14: 0.365
A15: Basis: Base case as in the write-up (management 4-5% organic growth guide; gradual margin expansion from refranchising/cost discipline). Bear assumes category growth stalls and input-cost/FX pressure compresses margin. Bull assumes above-guide volume/pricing and faster mix-driven margin expansion.

Sheet Comps
A1: COMPARABLE COMPANY ANALYSIS — GLOBAL BEVERAGE PEERS
A2: $ in millions except per-share and multiple data. Peer market data as of Aug 2026 snapshot (see notes for source variance).
A4: Company | B4: Price | C4: Market Cap | D4: Net Debt (est.) | E4: Enterprise Value | F4: P/E (TTM) | G4: EV/EBITDA
A5: PepsiCo (PEP) | B5: 142.62 | C5: 195460 | D5: 42963 | E5: =C5+D5 -> 238423 | F5: 27.2 | G5: 11.6
A6: Keurig Dr Pepper (KDP) | B6: 30.91 | C6: 43000 | D6: 25000 | E6: =C6+D6 -> 68000 | F6: 22.4 | G6: 12.1
A7: Monster Beverage (MNST) | B7: 70.03 | C7: 68090 | D7: -3419 | E7: =C7+D7 -> 64671 | F7: 42 | G7: n/a*
A9: Peer Average P/E | B9: =AVERAGE(F5:F7) -> 30.533333
A10: Peer Average EV/EBITDA | B10: =AVERAGE(G5:G7) -> 11.85
A12: Implied KO Valuation
A13: KO TTM EPS ($) | B13: =Historicals!B32 -> 3.33
A14: KO TTM EBITDA | B14: =Historicals!B34 -> 17217.225
A15: KO Net Debt (FY2025) | B15: =Historicals!F23 -> 32108
A16: KO Shares Outstanding (mm) | B16: =Summary!B7 -> 4301.6
A18: Method | B18: Implied Value | C18: Implied Value/Share
A19: P/E Implied Equity Value | B19: =B9*B13*B16 -> 437369.48 | C19: =B9*B13 -> 101.676
A20: EV/EBITDA Implied Equity Value | B20: =B10*B14-B15 -> 171916.12 | C20: =(B10*B14-B15)/B16 -> 39.965621
A22: Net Debt (PepsiCo, Monster): Total debt less cash & equivalents/short-term investments, per each company's Q2 FY2026 10-Q. Monster is debt-free (net cash).
A23: *Monster EV/EBITDA intentionally excluded from Peer Average EV/EBITDA: at ~32.8x (GuruFocus, TTM to Mar-26) it reflects a structurally higher growth/margin profile and would skew the 2-name PepsiCo/KDP average materially. Shown as n/a rather than blended in.
