Workbook

Sheet Summary
A1: NVIDIA CORPORATION (NASDAQ: NVDA) — EQUITY RESEARCH VALUATION
A2: Proof-of-work project — Private Equity / Equity Research portfolio
A3: All figures in USD billions unless noted. FY2024-FY2026 10-K data; market data as of Aug 28, 2026.
A5: Current Share Price | B5: ='Assumptions & WACC'!B5 -> 217.43
A6: Market Capitalization | B6: ='Assumptions & WACC'!B7 -> 5240.063
A7: WACC — Base Case | B7: ='Assumptions & WACC'!B16 -> 0.16365
A8: WACC — Bull Case | B8: ='Assumptions & WACC'!B21 -> 0.129
A10: Valuation Method | B10: Implied Value/Share | C10: vs. Current Price
A11: DCF — Base Case (beta 2.23) | B11: ='DCF Model'!B29 -> 132.95211 | C11: =B11/$B$5-1 -> -0.38852912
A12: DCF — Bull Case (beta 1.60) | B12: ='DCF Model'!B56 -> 225.51271 | C12: =B12/$B$5-1 -> 0.037173835
A13: Comps — Peer Avg. TTM P/E (reference only, see note) | B13: =Comps!B14 -> 400.09693 | C13: =B13/$B$5-1 -> 0.84011833
A15: Blended Fair Value (avg. of DCF base + bull only) | B15: =AVERAGE(B11:B12) -> 179.23241 | C15: =B15/$B$5-1 -> -0.17567764
A18: Football Field — Chart Data
A19: Method | B19: Base (invisible) | C19: Range (visible)
A20: DCF — Base Case | B20: =MIN('DCF Model'!B60:F64) -> 108.0533 | C20: =MAX('DCF Model'!B60:F64)-(MIN('DCF Model'!B60:F64)) -> 64.777688
A21: DCF — Bull Case | B21: =MIN('DCF Model'!B69:F73) -> 169.96974 | C21: =MAX('DCF Model'!B69:F73)-(MIN('DCF Model'!B69:F73)) -> 163.04505
A22: Current Price | B22: =$B$5*0.98 -> 213.0814 | C22: =$B$5*1.02-($B$5*0.98) -> 8.6972
A35: Recommendation
A36: HOLD. NVDA at $217 sits between a strict CAPM base case (using NVDA's reported 2.23 beta) and a bull case that requires treating NVDA's forward risk as meaningfully de-risked by its disclosed supply/backlog commitments. Near-term growth is high-confidence (FY27/FY28 substantially guided); the real debate is the discount rate the market should apply to a company this large, this fast-growing, and this dependent on a handful of hyperscaler capex decisions. See the accompanying report for the full thesis, catalysts, and risks.

Sheet Historicals
A1: NVIDIA CORPORATION — HISTORICAL FINANCIALS (FY2024-FY2026)
A2: Source: NVIDIA Form 10-K filings, FY2024-FY2026 (fiscal year ends last Sunday of January). $ in billions except per-share data.
A4: Fiscal Year | B4: FY2024A | C4: FY2025A | D4: FY2026A
A5: Total Revenue | B5: 60.922 | C5: 130.497 | D5: 215.9
A6: Revenue Growth % | B6: n/a | C6: =C5/B5-1 -> 1.1420341 | D6: =D5/C5-1 -> 0.65444416
A7: Gross Margin % (GAAP) | B7: 0.729 | C7: 0.75 | D7: 0.711
A8: Research & Development | B8: 8.675 | C8: 12.914 | D8: 18.497
A9: SG&A | B9: 2.654 | C9: 3.491 | D9: 4.579
A10: Operating Income (GAAP, approx.) | B10: 32.972 | C10: 81.453 | D10: 128.9
A11: Operating Margin % | B11: =B10/B5 -> 0.54121664 | C11: =C10/C5 -> 0.62417527 | D11: =D10/D5 -> 0.59703566
A12: Net Income (GAAP, approx.) | B12: 29.76 | C12: 72.88 | D12: 105.6
A13: Diluted EPS ($) | B13: 1.19 | C13: 2.94 | D13: 4.9
A15: Balance Sheet (selected)
A16: Cash, Equivalents & Short-Term Inv. | B16: 25.984 | C16: 43.21 | D16: 62.6
A17: Total Debt | B17: 9.709 | C17: 8.463 | D17: 10
A18: Net Cash | B18: =B16-B17 -> 16.275 | C18: =C16-C17 -> 34.747 | D18: =D16-D17 -> 52.6
A21: Quarterly Trend — FY2027 (current fiscal year)
A22: Quarter | B22: Q1 FY27A | C22: Q2 FY27A | D22: Q3 FY27E (guide)
A23: Revenue | B23: 81.615 | C23: 96.221 | D23: 108
A24: Data Center Revenue | B24: 75.246 | C24: 89.023 | D24: n/g
A25: GAAP Gross Margin % | B25: n/a | C25: 0.75 | D25: 0.74

Sheet Assumptions & WACC
A1: ASSUMPTIONS & WACC — BASE CASE VS. BULL CASE
A2: Blue = hardcoded input/assumption. Black = formula. Green = link to another tab.
A4: Market Data
A5: Current Share Price | B5: 217.43
A6: Shares Outstanding (bn) | B6: 24.1
A7: Market Capitalization ($bn) | B7: =B5*B6 -> 5240.063
A8: Net Cash ($bn, Q2 FY27) | B8: -11
A9: Tax Rate | B9: 0.18
A11: WACC — Base Case (reported CAPM beta)
A12: Risk-Free Rate (10Y UST) | B12: 0.041
A13: Equity Risk Premium | B13: 0.055
A14: Beta (5Y, as reported) | B14: 2.23
A15: Cost of Equity (base) | B15: =B12+B14*B13 -> 0.16365
A16: WACC (base) — debt negligible relative to market cap | B16: =B15 -> 0.16365
A18: WACC — Bull Case (“de-risked infrastructure” beta)
A19: Beta (bull case assumption) | B19: 1.6
A20: Cost of Equity (bull) | B20: =B12+B19*B13 -> 0.129
A21: WACC (bull) | B21: =B20 -> 0.129
A23: Revenue Build — FY2027E-FY2031E
A24: Driver | B24: FY2027E | C24: FY2028E | D24: FY2029E | E24: FY2030E | F24: FY2031E | G24: Basis
A25: Revenue Growth % — Base Case | B25: 0.875 | C25: 0.7 | D25: 0.35 | E25: 0.2 | F25: 0.13 | G25: FY27 built from Q1+Q2 actuals + Q3 guide + Q4 estimate; FY28 per company's own “~70%, supply-constrained” guidance; FY29-31 moderated sharply by this analysis as growth mathematically cannot stay near 70-100% at this revenue scale
A26: Revenue Growth % — Bull Case | B26: 0.875 | C26: 0.7 | D26: 0.45 | E26: 0.3 | F26: 0.2 | G26: Same FY27/FY28 as base case; FY29-31 assumes slower deceleration, consistent with management's characterization of underlying demand running closer to 100% than the supply-constrained 70% guide
A27: Operating Margin % | B27: 0.6 | C27: 0.61 | D27: 0.585 | E27: 0.57 | F27: 0.56 | G27: Q2 FY27 adj. operating margin was ~66.5%; held at a more conservative 56-61% range reflecting likely margin normalization as memory costs rise and competitive intensity increases
A28: D&A % of Revenue | B28: 0.025 | C28: 0.025 | D28: 0.025 | E28: 0.025 | F28: 0.025
A29: Capex % of Revenue | B29: 0.06 | C29: 0.065 | D29: 0.06 | E29: 0.055 | F29: 0.05 | G29: Reflects NVIDIA's own capacity/supply investment (rising near-term, moderating as the buildout matures)
A30: Incremental NWC % of Revenue Growth | B30: 0.02 | C30: 0.02 | D30: 0.02 | E30: 0.02 | F30: 0.02
A31: Terminal Growth Rate | B31: 0.035

Sheet DCF Model
A1: NVIDIA CORPORATION — DISCOUNTED CASH FLOW MODEL
A2: $ in billions except per-share data. Explicit forecast FY2027E-FY2031E, built and discounted separately under base-case and bull-case scenarios.
A4: BASE CASE — Reported Beta (2.23), WACC ~16.4%
A5: Fiscal Year | B5: FY2026A | C5: FY2027E | D5: FY2028E | E5: FY2029E | F5: FY2030E | G5: FY2031E
A6: Revenue Growth % | B6: n/a | C6: ='Assumptions & WACC'!B25 -> 0.875 | D6: ='Assumptions & WACC'!C25 -> 0.7 | E6: ='Assumptions & WACC'!D25 -> 0.35 | F6: ='Assumptions & WACC'!E25 -> 0.2 | G6: ='Assumptions & WACC'!F25 -> 0.13
A7: Revenue | B7: =Historicals!D5 -> 215.9 | C7: =B7*(1+C6) -> 404.8125 | D7: =C7*(1+D6) -> 688.18125 | E7: =D7*(1+E6) -> 929.04469 | F7: =E7*(1+F6) -> 1114.8536 | G7: =F7*(1+G6) -> 1259.7846
A8: Operating Margin % | C8: ='Assumptions & WACC'!B27 -> 0.6 | D8: ='Assumptions & WACC'!C27 -> 0.61 | E8: ='Assumptions & WACC'!D27 -> 0.585 | F8: ='Assumptions & WACC'!E27 -> 0.57 | G8: ='Assumptions & WACC'!F27 -> 0.56
A9: Operating Income (EBIT) | C9: =C7*C8 -> 242.8875 | D9: =D7*D8 -> 419.79056 | E9: =E7*E8 -> 543.49114 | F9: =F7*F8 -> 635.46657 | G9: =G7*G8 -> 705.47937
A10: NOPAT | C10: =C9*(1-'Assumptions & WACC'!$B$9) -> 199.16775 | D10: =D9*(1-'Assumptions & WACC'!$B$9) -> 344.22826 | E10: =E9*(1-'Assumptions & WACC'!$B$9) -> 445.66274 | F10: =F9*(1-'Assumptions & WACC'!$B$9) -> 521.08258 | G10: =G9*(1-'Assumptions & WACC'!$B$9) -> 578.49309
A11: (+) D&A | C11: =C7*'Assumptions & WACC'!B28 -> 10.120313 | D11: =D7*'Assumptions & WACC'!C28 -> 17.204531 | E11: =E7*'Assumptions & WACC'!D28 -> 23.226117 | F11: =F7*'Assumptions & WACC'!E28 -> 27.871341 | G11: =G7*'Assumptions & WACC'!F28 -> 31.494615
A12: (-) Capital Expenditures | C12: =C7*'Assumptions & WACC'!B29 -> 24.28875 | D12: =D7*'Assumptions & WACC'!C29 -> 44.731781 | E12: =E7*'Assumptions & WACC'!D29 -> 55.742681 | F12: =F7*'Assumptions & WACC'!E29 -> 61.316949 | G12: =G7*'Assumptions & WACC'!F29 -> 62.98923
A13: (-) Incremental NWC | C13: =(C7-B7)*'Assumptions & WACC'!B30 -> 3.77825 | D13: =(D7-C7)*'Assumptions & WACC'!C30 -> 5.667375 | E13: =(E7-D7)*'Assumptions & WACC'!D30 -> 4.8172688 | F13: =(F7-E7)*'Assumptions & WACC'!E30 -> 3.7161788 | G13: =(G7-F7)*'Assumptions & WACC'!F30 -> 2.8986194
A14: Unlevered Free Cash Flow | C14: =C10+C11-C12-C13 -> 181.22106 | D14: =D10+D11-D12-D13 -> 311.03364 | E14: =E10+E11-E12-E13 -> 408.3289 | F14: =F10+F11-F12-F13 -> 483.9208 | G14: =G10+G11-G12-G13 -> 544.09985
A15: Discount Period | C15: 1 | D15: 2 | E15: 3 | F15: 4 | G15: 5
A16: Discount Factor | C16: =1/(1+'Assumptions & WACC'!$B$16)^C15 -> 0.85936493 | D16: =1/(1+'Assumptions & WACC'!$B$16)^D15 -> 0.73850808 | E16: =1/(1+'Assumptions & WACC'!$B$16)^E15 -> 0.63464795 | F16: =1/(1+'Assumptions & WACC'!$B$16)^F15 -> 0.54539419 | G16: =1/(1+'Assumptions & WACC'!$B$16)^G15 -> 0.46869264
A17: PV of Unlevered FCF | C17: =C14*C16 -> 155.73503 | D17: =D14*D16 -> 229.70085 | E17: =E14*E16 -> 259.1451 | F17: =F14*F16 -> 263.92759 | G17: =G14*G16 -> 255.01559
A19: Terminal Growth Rate | B19: ='Assumptions & WACC'!B31 -> 0.035
A20: Terminal Value (undiscounted) | B20: =G14*(1+B19)/('Assumptions & WACC'!$B$16-B19) -> 4377.3288
A21: PV of Terminal Value | B21: =B20*G16 -> 2051.6218
A23: Sum of PV of Explicit FCF | B23: =SUM(C17:G17) -> 1163.5242
A24: (+) PV of Terminal Value | B24: =B21 -> 2051.6218
A25: Enterprise Value | B25: =B23+B21 -> 3215.1459
A26: (+) Net Cash / (Net Debt) | B26: ='Assumptions & WACC'!B8 -> -11
A27: Implied Equity Value | B27: =B25+B26 -> 3204.1459
A28: Shares Outstanding (bn) | B28: ='Assumptions & WACC'!B6 -> 24.1
A29: Implied Value per Share | B29: =B27/B28 -> 132.95211
A31: BULL CASE — De-Risked Beta (1.60), WACC ~12.9%
A32: Fiscal Year | B32: FY2026A | C32: FY2027E | D32: FY2028E | E32: FY2029E | F32: FY2030E | G32: FY2031E
A33: Revenue Growth % | B33: n/a | C33: ='Assumptions & WACC'!B26 -> 0.875 | D33: ='Assumptions & WACC'!C26 -> 0.7 | E33: ='Assumptions & WACC'!D26 -> 0.45 | F33: ='Assumptions & WACC'!E26 -> 0.3 | G33: ='Assumptions & WACC'!F26 -> 0.2
A34: Revenue | B34: =Historicals!D5 -> 215.9 | C34: =B34*(1+C33) -> 404.8125 | D34: =C34*(1+D33) -> 688.18125 | E34: =D34*(1+E33) -> 997.86281 | F34: =E34*(1+F33) -> 1297.2217 | G34: =F34*(1+G33) -> 1556.666
A35: Operating Margin % | C35: ='Assumptions & WACC'!B27 -> 0.6 | D35: ='Assumptions & WACC'!C27 -> 0.61 | E35: ='Assumptions & WACC'!D27 -> 0.585 | F35: ='Assumptions & WACC'!E27 -> 0.57 | G35: ='Assumptions & WACC'!F27 -> 0.56
A36: Operating Income (EBIT) | C36: =C34*C35 -> 242.8875 | D36: =D34*D35 -> 419.79056 | E36: =E34*E35 -> 583.74975 | F36: =F34*F35 -> 739.41634 | G36: =G34*G35 -> 871.73295
A37: NOPAT | C37: =C36*(1-'Assumptions & WACC'!$B$9) -> 199.16775 | D37: =D36*(1-'Assumptions & WACC'!$B$9) -> 344.22826 | E37: =E36*(1-'Assumptions & WACC'!$B$9) -> 478.67479 | F37: =F36*(1-'Assumptions & WACC'!$B$9) -> 606.3214 | G37: =G36*(1-'Assumptions & WACC'!$B$9) -> 714.82102
A38: (+) D&A | C38: =C34*'Assumptions & WACC'!B28 -> 10.120313 | D38: =D34*'Assumptions & WACC'!C28 -> 17.204531 | E38: =E34*'Assumptions & WACC'!D28 -> 24.94657 | F38: =F34*'Assumptions & WACC'!E28 -> 32.430541 | G38: =G34*'Assumptions & WACC'!F28 -> 38.91665
A39: (-) Capital Expenditures | C39: =C34*'Assumptions & WACC'!B29 -> 24.28875 | D39: =D34*'Assumptions & WACC'!C29 -> 44.731781 | E39: =E34*'Assumptions & WACC'!D29 -> 59.871769 | F39: =F34*'Assumptions & WACC'!E29 -> 71.347191 | G39: =G34*'Assumptions & WACC'!F29 -> 77.833299
A40: (-) Incremental NWC | C40: =(C34-B34)*'Assumptions & WACC'!B30 -> 3.77825 | D40: =(D34-C34)*'Assumptions & WACC'!C30 -> 5.667375 | E40: =(E34-D34)*'Assumptions & WACC'!D30 -> 6.1936313 | F40: =(F34-E34)*'Assumptions & WACC'!E30 -> 5.9871769 | G40: =(G34-F34)*'Assumptions & WACC'!F30 -> 5.1888866
A41: Unlevered Free Cash Flow | C41: =C37+C38-C39-C40 -> 181.22106 | D41: =D37+D38-D39-D40 -> 311.03364 | E41: =E37+E38-E39-E40 -> 437.55596 | F41: =F37+F38-F39-F40 -> 561.41758 | G41: =G37+G38-G39-G40 -> 670.71549
A42: Discount Period | C42: 1 | D42: 2 | E42: 3 | F42: 4 | G42: 5
A43: Discount Factor | C43: =1/(1+'Assumptions & WACC'!$B$21)^C42 -> 0.88573959 | D43: =1/(1+'Assumptions & WACC'!$B$21)^D42 -> 0.78453463 | E43: =1/(1+'Assumptions & WACC'!$B$21)^E42 -> 0.69489338 | F43: =1/(1+'Assumptions & WACC'!$B$21)^F42 -> 0.61549458 | G43: =1/(1+'Assumptions & WACC'!$B$21)^G42 -> 0.54516792
A44: PV of Unlevered FCF | C44: =C41*C43 -> 160.51467 | D44: =D41*D43 -> 244.01666 | E44: =E41*E43 -> 304.05474 | F44: =F41*F43 -> 345.54947 | G44: =G41*G43 -> 365.65256
...

Sheet Comps
A1: COMPARABLE COMPANY ANALYSIS — SEMICONDUCTOR / AI INFRASTRUCTURE PEERS
A2: $ in billions except per-share and multiple data. Peer market data snapshot, Aug 24–28, 2026.
A4: Company | B4: Price | C4: Beta | D4: Revenue (TTM) | E4: Net Income (TTM) | F4: P/E (TTM) | G4: P/E (Fwd) | H4: EV/EBITDA
A5: NVIDIA (NVDA) | B5: 217.43 | C5: 2.23 | D5: 138 | E5: 105.6 | F5: 27.48 | G5: n/a | H5: n/a
A6: AMD | B6: 468.28 | C6: 2.49 | D6: 41.31 | E6: 6.43 | F6: 120.79 | G6: 42.61 | H6: 79.87
A7: Broadcom (AVGO) | B7: 380 | C7: 1.47 | D7: 75.47 | E7: 29.32 | F7: 61.83 | G7: 23.55 | H7: 43.08
A9: Peer (ex-NVDA) Average P/E (TTM) | B9: =AVERAGE(F6:F7) -> 91.31
A10: Peer (ex-NVDA) Average P/E (Fwd) | B10: =AVERAGE(G6:G7) -> 33.08
A12: Implied NVDA Valuation — Peer Multiple Cross-Check
A13: NVDA TTM EPS ($) | B13: =E5/'Assumptions & WACC'!B6 -> 4.3817427
A14: Applying peer avg. TTM P/E | B14: =B9*B13 -> 400.09693
A15: Applying peer avg. Fwd P/E (to FY28E EPS proxy) | B15: =B10*B13*1.85 -> 268.15389
