Workbook

Sheet Cover
B3: Qualys, Inc. (NASDAQ: QLYS)
B4: Illustrative Leveraged Buyout (LBO) Analysis
B6: Prepared for portfolio / interview case-study purposes — Investment Banking, Private Equity & VC Analyst candidature
B8: Valuation / Entry Date: | C8: April 9, 2026
B9: Sector: | C9: Cybersecurity / Cloud IT Security & Compliance (SaaS)
B10: Ticker / Exchange: | C10: QLYS / NASDAQ
B12: Contents
B13: Assumptions | C13: Transaction, operating, financing & exit assumptions
B14: Sources & Uses | C14: Purchase price funding structure at close
B15: Operating Model | C15: 5-year revenue, EBITDA, and free cash flow build
B16: Debt Schedule | C16: Term Loan B amortization, cash sweep & interest
B17: Returns Analysis | C17: Exit proceeds, IRR / MOIC and sensitivity tables
B19: Color & Formatting Legend
B20: ● | C20: Blue text — hardcoded input / assumption you can change
B21: ● | C21: Blue text, yellow fill — key value/return driver (flex this first)
B22: ● | C22: Black text — formula calculated within the same sheet
B23: ● | C23: Green text — formula linking to another sheet
B24: Key assumption
B26: Basis of Preparation & Disclaimer
B27: This is an independently-built, illustrative model using Qualys' publicly reported financial results (FY2025 earnings release, Feb 5, 2026; FY2026 guidance) and third-party market data (share price, shares outstanding, cash and debt) as of on/around April 9, 2026, cited in cell comments where used. It is a hypothetical case study built to demonstrate LBO modeling technique — it is not a real transaction, is not investment advice, and Qualys is not known to be an actual buyout target. All forward-looking assumptions (growth, margins, leverage, exit multiple) are the modeler's own and are clearly flagged as editable inputs.

Sheet Assumptions
B2: Qualys, Inc. (QLYS) — LBO Model: Assumptions
B4: A. Market Data & LTM Financials (Entry)
B5: Valuation / pricing date | C5: 4/9/2026
B6: Current share price ($/sh) | C6: 76.14
B7: Diluted shares outstanding (mm) | C7: 36.3
B8: Current market capitalization ($mm) | C8: =C6*C7 -> 2763.882
B9: LTM revenue — FY2025A ($mm) | C9: 669.1
B10: LTM Adjusted EBITDA — FY2025A ($mm) | C10: 313.4
B11: LTM Adjusted EBITDA margin (%) | C11: =C10/C9 -> 0.46839038
B12: Cash, cash equivalents & marketable securities ($mm) | C12: 445.9
B13: Total debt outstanding ($mm) | C13: 0
B14: Net debt / (net cash) ($mm) | C14: =C13-C12 -> -445.9
B16: B. Entry Valuation & Take-Private Offer
B17: Entry EV / LTM EBITDA multiple | C17: 10
B18: Entry enterprise value ($mm) | C18: =C17*C10 -> 3134
B19: Plus: cash acquired (cash-free / debt-free basis) ($mm) | C19: =C12 -> 445.9
B20: Less: debt assumed ($mm) | C20: =-C13 -> 0
B21: Implied equity purchase price ($mm) | C21: =C18+C19+C20 -> 3579.9
B22: Implied offer price ($/share) | C22: =C21/C7 -> 98.619835
B23: Implied premium to current share price (%) | C23: =C22/C6-1 -> 0.29524343
B25: C. Operating Assumptions — FY2026E to FY2030E
C26: FY2025A (LTM) | D26: FY2026E | E26: FY2027E | F26: FY2028E | G26: FY2029E | H26: FY2030E
B27: Revenue growth, % YoY | D27: 0.077 | E27: 0.08 | F27: 0.08 | G27: 0.075 | H27: 0.07
B28: Adjusted EBITDA margin, % | D28: 0.45 | E28: 0.455 | F28: 0.46 | G28: 0.465 | H28: 0.47
B29: D&A, % of revenue | D29: 0.03 | E29: 0.03 | F29: 0.03 | G29: 0.03 | H29: 0.03
B30: Capital expenditures, % of revenue | D30: 0.015 | E30: 0.015 | F30: 0.015 | G30: 0.015 | H30: 0.015
B31: Change in net working capital, % of Δ revenue (source)/(use) | D31: 0.02 | E31: 0.02 | F31: 0.02 | G31: 0.02 | H31: 0.02
B32: Cash tax rate, % | D32: 0.25
B34: D. Financing Assumptions
B35: Entry leverage — Term Loan B (x LTM EBITDA) | C35: 4.5
B36: New Term Loan B ($mm) | C36: =C35*C10 -> 1410.3
B37: Term Loan B interest rate, all-in (SOFR + margin) | C37: 0.085
B38: Mandatory amortization, % of original principal p.a. | C38: 0.01
B39: Cash flow sweep, % of excess free cash flow | C39: 1
B40: Minimum cash balance retained ($mm) | C40: 50
B41: Transaction fees (advisory/legal), % of entry EV | C41: 0.015
B42: Financing fees, % of new debt raised | C42: 0.02
B44: E. Exit Assumptions
B45: Hold period (years) | C45: 5
B46: Exit EV / EBITDA multiple | C46: 10
...

Sheet Sources & Uses
B2: Qualys, Inc. (QLYS) — Sources & Uses at Close
B4: Uses of Funds
B5: $mm
B6: Purchase of equity | C6: =Assumptions!C21 -> 3579.9
B7: Refinance existing debt | C7: =Assumptions!C13 -> 0
B8: Transaction fees (advisory / legal) | C8: =Assumptions!C18*Assumptions!C41 -> 47.01
B9: Financing fees (new debt) | C9: =C14*Assumptions!C42 -> 28.206
B10: Total uses | C10: =SUM(C6:C9) -> 3655.116
B12: Sources of Funds
B13: $mm
B14: New Term Loan B | C14: =Assumptions!C36 -> 1410.3
B15: Cash used from target balance sheet | C15: =Assumptions!C12-Assumptions!C40 -> 395.9
B16: Sponsor (PE fund) equity — plug | C16: =C10-C14-C15 -> 1848.916
B17: Total sources | C17: =SUM(C14:C16) -> 3655.116
B19: Checks & Capitalization
B20: Check: total sources − total uses (should be $0) | C20: =C17-C10 -> 0
B21: Entry leverage (Debt / LTM EBITDA) | C21: =C14/Assumptions!C10 -> 4.5
B22: Sponsor equity as % of total capitalization | C22: =C16/C17 -> 0.50584332
B23: Debt as % of total capitalization | C23: =C14/C17 -> 0.38584275
B25: Sponsor equity is solved as the plug needed to fund total uses after new debt and target balance-sheet cash. This equity check is a standard sanity test on every LBO Sources & Uses table.

Sheet Operating Model
B2: Qualys, Inc. (QLYS) — Operating Model & Free Cash Flow Build ($mm)
C4: FY2025A (LTM) | D4: FY2026E | E4: FY2027E | F4: FY2028E | G4: FY2029E | H4: FY2030E
B5: Income Statement
B6: Revenue growth, % YoY | D6: =Assumptions!D27 -> 0.077 | E6: =Assumptions!E27 -> 0.08 | F6: =Assumptions!F27 -> 0.08 | G6: =Assumptions!G27 -> 0.075 | H6: =Assumptions!H27 -> 0.07
B7: Revenue | C7: =Assumptions!C9 -> 669.1 | D7: =C7*(1+D6) -> 720.6207 | E7: =D7*(1+E6) -> 778.27036 | F7: =E7*(1+F6) -> 840.53198 | G7: =F7*(1+G6) -> 903.57188 | H7: =G7*(1+H6) -> 966.82192
B8: Adjusted EBITDA margin, % | C8: =Assumptions!C10/Assumptions!C9 -> 0.46839038 | D8: =Assumptions!D28 -> 0.45 | E8: =Assumptions!E28 -> 0.455 | F8: =Assumptions!F28 -> 0.46 | G8: =Assumptions!G28 -> 0.465 | H8: =Assumptions!H28 -> 0.47
B9: Adjusted EBITDA | C9: =Assumptions!C10 -> 313.4 | D9: =D7*D8 -> 324.27931 | E9: =E7*E8 -> 354.11301 | F9: =F7*F8 -> 386.64471 | G9: =G7*G8 -> 420.16093 | H9: =H7*H8 -> 454.4063
B10: Less: depreciation & amortization | D10: =-D7*Assumptions!D29 -> -21.618621 | E10: =-E7*Assumptions!E29 -> -23.348111 | F10: =-F7*Assumptions!F29 -> -25.21596 | G10: =-G7*Assumptions!G29 -> -27.107156 | H10: =-H7*Assumptions!H29 -> -29.004657
B11: EBIT | D11: =D9+D10 -> 302.66069 | E11: =E9+E10 -> 330.7649 | F11: =F9+F10 -> 361.42875 | G11: =G9+G10 -> 393.05377 | H11: =H9+H10 -> 425.40164
B12: Less: cash interest expense | D12: =-'Debt Schedule'!D9 -> -119.8755 | E12: =-'Debt Schedule'!E9 -> -107.21657 | F12: =-'Debt Schedule'!F9 -> -91.875062 | G12: =-'Debt Schedule'!G9 -> -73.513491 | H12: =-'Debt Schedule'!H9 -> -51.883576
B13: Pre-tax income (EBT) | D13: =D11+D12 -> 182.78519 | E13: =E11+E12 -> 223.54833 | F13: =F11+F12 -> 269.55369 | G13: =G11+G12 -> 319.54028 | H13: =H11+H12 -> 373.51807
B14: Less: cash taxes | D14: =-MAX(D13,0)*Assumptions!$D$32 -> -45.696298 | E14: =-MAX(E13,0)*Assumptions!$D$32 -> -55.887084 | F14: =-MAX(F13,0)*Assumptions!$D$32 -> -67.388423 | G14: =-MAX(G13,0)*Assumptions!$D$32 -> -79.88507 | H14: =-MAX(H13,0)*Assumptions!$D$32 -> -93.379517
B15: Net income | D15: =D13+D14 -> 137.0889 | E15: =E13+E14 -> 167.66125 | F15: =F13+F14 -> 202.16527 | G15: =G13+G14 -> 239.65521 | H15: =H13+H14 -> 280.13855
B17: Free Cash Flow Available for Debt Repayment
B18: Adjusted EBITDA | D18: =D9 -> 324.27931 | E18: =E9 -> 354.11301 | F18: =F9 -> 386.64471 | G18: =G9 -> 420.16093 | H18: =H9 -> 454.4063
B19: Less: capital expenditures | D19: =-D7*Assumptions!D30 -> -10.809311 | E19: =-E7*Assumptions!E30 -> -11.674055 | F19: =-F7*Assumptions!F30 -> -12.60798 | G19: =-G7*Assumptions!G30 -> -13.553578 | H19: =-H7*Assumptions!H30 -> -14.502329
B20: Plus/(less): change in net working capital | D20: =(D7-C7)*Assumptions!D31 -> 1.030414 | E20: =(E7-D7)*Assumptions!E31 -> 1.1529931 | F20: =(F7-E7)*Assumptions!F31 -> 1.2452326 | G20: =(G7-F7)*Assumptions!G31 -> 1.260798 | H20: =(H7-G7)*Assumptions!H31 -> 1.2650006
B21: Less: cash interest expense | D21: =D12 -> -119.8755 | E21: =E12 -> -107.21657 | F21: =F12 -> -91.875062 | G21: =G12 -> -73.513491 | H21: =H12 -> -51.883576
B22: Less: cash taxes | D22: =D14 -> -45.696298 | E22: =E14 -> -55.887084 | F22: =F14 -> -67.388423 | G22: =G14 -> -79.88507 | H22: =H14 -> -93.379517
B23: Less: mandatory debt amortization | D23: =-'Debt Schedule'!D10 -> -14.103 | E23: =-'Debt Schedule'!E10 -> -14.103 | F23: =-'Debt Schedule'!F10 -> -14.103 | G23: =-'Debt Schedule'!G10 -> -14.103 | H23: =-'Debt Schedule'!H10 -> -14.103
B24: Cash flow available for optional debt repayment | D24: =SUM(D18:D23) -> 134.82562 | E24: =SUM(E18:E23) -> 166.3853 | F24: =SUM(F18:F23) -> 201.91548 | G24: =SUM(G18:G23) -> 240.36658 | H24: =SUM(H18:H23) -> 281.80288
B25: Optional prepayment (cash flow sweep) | D25: =-'Debt Schedule'!D19 -> -134.82562 | E25: =-'Debt Schedule'!E19 -> -166.3853 | F25: =-'Debt Schedule'!F19 -> -201.91548 | G25: =-'Debt Schedule'!G19 -> -240.36658 | H25: =-'Debt Schedule'!H19 -> -281.80288
B26: Increase / (decrease) in cash balance | D26: =D24+D25 -> 0 | E26: =E24+E25 -> 0 | F26: =F24+F25 -> 0 | G26: =G24+G25 -> 0 | H26: =H24+H25 -> 0
B28: Interest expense and debt paydown are linked from the Debt Schedule tab, which sizes cash interest off the beginning-of-year loan balance (no circularity: prior-year ending balance is known at the start of each period).

Sheet Debt Schedule
B2: Qualys, Inc. (QLYS) — Term Loan B Debt Schedule ($mm)
B4: 100% cash flow sweep after mandatory amortization, capex, cash interest and cash taxes. Interest accrues on the beginning-of-year balance (no circularity).
C6: At Close | D6: FY2026E | E6: FY2027E | F6: FY2028E | G6: FY2029E | H6: FY2030E
B7: Beginning Term Loan B balance | C7: ='Sources & Uses'!C14 -> 1410.3 | D7: =C7 -> 1410.3 | E7: =D21 -> 1261.3714 | F7: =E21 -> 1080.8831 | G7: =F21 -> 864.8646 | H7: =G21 -> 610.39502
B8: Interest rate, all-in | D8: =Assumptions!$C$37 -> 0.085 | E8: =Assumptions!$C$37 -> 0.085 | F8: =Assumptions!$C$37 -> 0.085 | G8: =Assumptions!$C$37 -> 0.085 | H8: =Assumptions!$C$37 -> 0.085
B9: Cash interest expense | D9: =D7*D8 -> 119.8755 | E9: =E7*E8 -> 107.21657 | F9: =F7*F8 -> 91.875062 | G9: =G7*G8 -> 73.513491 | H9: =H7*H8 -> 51.883576
B10: Mandatory amortization | D10: ='Sources & Uses'!$C$14*Assumptions!$C$38 -> 14.103 | E10: ='Sources & Uses'!$C$14*Assumptions!$C$38 -> 14.103 | F10: ='Sources & Uses'!$C$14*Assumptions!$C$38 -> 14.103 | G10: ='Sources & Uses'!$C$14*Assumptions!$C$38 -> 14.103 | H10: ='Sources & Uses'!$C$14*Assumptions!$C$38 -> 14.103
B11: Cash Available for Optional Prepayment
B12: Adjusted EBITDA | D12: ='Operating Model'!D9 -> 324.27931 | E12: ='Operating Model'!E9 -> 354.11301 | F12: ='Operating Model'!F9 -> 386.64471 | G12: ='Operating Model'!G9 -> 420.16093 | H12: ='Operating Model'!H9 -> 454.4063
B13: Less: capital expenditures | D13: ='Operating Model'!D19 -> -10.809311 | E13: ='Operating Model'!E19 -> -11.674055 | F13: ='Operating Model'!F19 -> -12.60798 | G13: ='Operating Model'!G19 -> -13.553578 | H13: ='Operating Model'!H19 -> -14.502329
B14: Plus/(less): change in net working capital | D14: ='Operating Model'!D20 -> 1.030414 | E14: ='Operating Model'!E20 -> 1.1529931 | F14: ='Operating Model'!F20 -> 1.2452326 | G14: ='Operating Model'!G20 -> 1.260798 | H14: ='Operating Model'!H20 -> 1.2650006
B15: Less: cash interest expense | D15: =-D9 -> -119.8755 | E15: =-E9 -> -107.21657 | F15: =-F9 -> -91.875062 | G15: =-G9 -> -73.513491 | H15: =-H9 -> -51.883576
B16: Less: cash taxes | D16: ='Operating Model'!D14 -> -45.696298 | E16: ='Operating Model'!E14 -> -55.887084 | F16: ='Operating Model'!F14 -> -67.388423 | G16: ='Operating Model'!G14 -> -79.88507 | H16: ='Operating Model'!H14 -> -93.379517
B17: Less: mandatory amortization | D17: =-D10 -> -14.103 | E17: =-E10 -> -14.103 | F17: =-F10 -> -14.103 | G17: =-G10 -> -14.103 | H17: =-H10 -> -14.103
B18: Cash flow available for optional prepayment | D18: =SUM(D12:D17) -> 134.82562 | E18: =SUM(E12:E17) -> 166.3853 | F18: =SUM(F12:F17) -> 201.91548 | G18: =SUM(G12:G17) -> 240.36658 | H18: =SUM(H12:H17) -> 281.80288
B19: Optional prepayment (cash flow sweep) | D19: =MIN(MAX(D18,0),D7-D10)*Assumptions!$C$39 -> 134.82562 | E19: =MIN(MAX(E18,0),E7-E10)*Assumptions!$C$39 -> 166.3853 | F19: =MIN(MAX(F18,0),F7-F10)*Assumptions!$C$39 -> 201.91548 | G19: =MIN(MAX(G18,0),G7-G10)*Assumptions!$C$39 -> 240.36658 | H19: =MIN(MAX(H18,0),H7-H10)*Assumptions!$C$39 -> 281.80288
B21: Ending Term Loan B balance | D21: =D7-D10-D19 -> 1261.3714 | E21: =E7-E10-E19 -> 1080.8831 | F21: =F7-F10-F19 -> 864.8646 | G21: =G7-G10-G19 -> 610.39502 | H21: =H7-H10-H19 -> 314.48914
B23: Total debt / LTM EBITDA at year-end | D23: =D21/Assumptions!$C$10 -> 4.024797 | E23: =E21/Assumptions!$C$10 -> 3.448893 | F23: =F21/Assumptions!$C$10 -> 2.759619 | G23: =G21/Assumptions!$C$10 -> 1.9476548 | H23: =H21/Assumptions!$C$10 -> 1.0034752
B25: Cash interest is computed on the beginning-of-year balance to avoid a circular reference; this is a standard simplification versus an average-balance or fully circular approach.

Sheet Returns Analysis
B2: Qualys, Inc. (QLYS) — Exit Proceeds, IRR & MOIC
B4: Base Case Exit (Year 5 / FY2030E)
B5: Exit year Adjusted EBITDA (FY2030E) | C5: ='Operating Model'!H9 -> 454.4063
B6: Exit EV / EBITDA multiple | C6: =Assumptions!C46 -> 10
B7: Exit enterprise value | C7: =C5*C6 -> 4544.063
B8: Less: net debt at exit | C8: =-'Debt Schedule'!H21 -> -314.48914
B9: Less: exit transaction fees | C9: =-C7*Assumptions!C47 -> -45.44063
B10: Plus: minimum cash balance retained | C10: =Assumptions!C40 -> 50
B11: Exit equity value to sponsor | C11: =SUM(C7:C10) -> 4234.1332
B13: Sponsor Returns
B14: Sponsor initial equity investment (Year 0) | C14: ='Sources & Uses'!C16 -> 1848.916
B15: Exit equity value to sponsor (Year 5) | C15: =C11 -> 4234.1332
B16: Hold period (years) | C16: =Assumptions!C45 -> 5
B17: Multiple of invested capital (MOIC) | C17: =C11/C14 -> 2.2900625
B18: Gross IRR | C18: =C17^(1/C16)-1 -> 0.18023766
B20: Cash-flow check (Year 0–Year 5) for Excel IRR() verification
C21: =-C14 -> -1848.916 | D21: =0 -> 0 | E21: =0 -> 0 | F21: =0 -> 0 | G21: =0 -> 0 | H21: =C11 -> 4234.1332
B22: IRR (Excel IRR function, cross-check) | C22: =IRR(C21:H21) -> 0.18023766
B24: Sensitivity: Entry Leverage vs. Exit Multiple
B25: Approximation: holds Year-5 EBITDA and the pace of debt paydown (mandatory amortization + cumulative FCF sweep capacity) constant across leverage scenarios, i.e. it assumes the modest change in interest expense from a different starting debt load does not materially change cumulative free cash flow available for sweep over the hold. Everything else flexes dynamically from the assumptions above.
B27: Helper calcs →
B28: Entry leverage (x EBITDA) | C28: 3.5 | D28: 4 | E28: 4.5 | F28: 5 | G28: 5.5
B29: Entry Term Loan B ($mm) | C29: =C28*Assumptions!$C$10 -> 1096.9 | D29: =D28*Assumptions!$C$10 -> 1253.6 | E29: =E28*Assumptions!$C$10 -> 1410.3 | F29: =F28*Assumptions!$C$10 -> 1567 | G29: =G28*Assumptions!$C$10 -> 1723.7
B30: Financing fees ($mm) | C30: =C29*Assumptions!$C$42 -> 21.938 | D30: =D29*Assumptions!$C$42 -> 25.072 | E30: =E29*Assumptions!$C$42 -> 28.206 | F30: =F29*Assumptions!$C$42 -> 31.34 | G30: =G29*Assumptions!$C$42 -> 34.474
B31: Total uses ($mm) | C31: =Assumptions!$C$21+Assumptions!$C$18*Assumptions!$C$41+C30 -> 3648.848 | D31: =Assumptions!$C$21+Assumptions!$C$18*Assumptions!$C$41+D30 -> 3651.982 | E31: =Assumptions!$C$21+Assumptions!$C$18*Assumptions!$C$41+E30 -> 3655.116 | F31: =Assumptions!$C$21+Assumptions!$C$18*Assumptions!$C$41+F30 -> 3658.25 | G31: =Assumptions!$C$21+Assumptions!$C$18*Assumptions!$C$41+G30 -> 3661.384
B32: Sponsor equity ($mm) | C32: =C31-C29-(Assumptions!$C$12-Assumptions!$C$40) -> 2156.048 | D32: =D31-D29-(Assumptions!$C$12-Assumptions!$C$40) -> 2002.482 | E32: =E31-E29-(Assumptions!$C$12-Assumptions!$C$40) -> 1848.916 | F32: =F31-F29-(Assumptions!$C$12-Assumptions!$C$40) -> 1695.35 | G32: =G31-G29-(Assumptions!$C$12-Assumptions!$C$40) -> 1541.784
B33: Cumulative 5-yr debt paydown capacity ($mm) | C33: ='Debt Schedule'!C7-'Debt Schedule'!H21 -> 1095.8109
B34: Year-5 debt at this leverage ($mm) | C34: =MAX(0,C29-$C$33) -> 1.0891361 | D34: =MAX(0,D29-$C$33) -> 157.78914 | E34: =MAX(0,E29-$C$33) -> 314.48914 | F34: =MAX(0,F29-$C$33) -> 471.18914 | G34: =MAX(0,G29-$C$33) -> 627.88914
B36: Gross IRR grid
B37: Exit multiple ↓ / Entry leverage → | C37: =C28 -> 3.5 | D37: =D28 -> 4 | E37: =E28 -> 4.5 | F37: =F28 -> 5 | G37: =G28 -> 5.5
B38: 8 | C38: =((($B38*C5)-C34-($B38*C5)*Assumptions!$C$47+Assumptions!$C$40)/C32)^(1/Assumptions!$C$45)-1 -> 0.11089939 | D38: =((($B38*C5)-D34-($B38*C5)*Assumptions!$C$47+Assumptions!$C$40)/D32)^(1/Assumptions!$C$45)-1 -> 0.11758085 | E38: =((($B38*C5)-E34-($B38*C5)*Assumptions!$C$47+Assumptions!$C$40)/E32)^(1/Assumptions!$C$45)-1 -> 0.12517567 | F38: =((($B38*C5)-F34-($B38*C5)*Assumptions!$C$47+Assumptions!$C$40)/F32)^(1/Assumptions!$C$45)-1 -> 0.13389005 | G38: =((($B38*C5)-G34-($B38*C5)*Assumptions!$C$47+Assumptions!$C$40)/G32)^(1/Assumptions!$C$45)-1 -> 0.14399912
B39: 9 | C39: =((($B39*C5)-C34-($B39*C5)*Assumptions!$C$47+Assumptions!$C$40)/C32)^(1/Assumptions!$C$45)-1 -> 0.13703997 | D39: =((($B39*C5)-D34-($B39*C5)*Assumptions!$C$47+Assumptions!$C$40)/D32)^(1/Assumptions!$C$45)-1 -> 0.14500379 | E39: =((($B39*C5)-E34-($B39*C5)*Assumptions!$C$47+Assumptions!$C$40)/E32)^(1/Assumptions!$C$45)-1 -> 0.15401913 | F39: =((($B39*C5)-F34-($B39*C5)*Assumptions!$C$47+Assumptions!$C$40)/F32)^(1/Assumptions!$C$45)-1 -> 0.16431719 | G39: =((($B39*C5)-G34-($B39*C5)*Assumptions!$C$47+Assumptions!$C$40)/G32)^(1/Assumptions!$C$45)-1 -> 0.17620491
B40: 10 | C40: =((($B40*C5)-C34-($B40*C5)*Assumptions!$C$47+Assumptions!$C$40)/C32)^(1/Assumptions!$C$45)-1 -> 0.16097667 | D40: =((($B40*C5)-D34-($B40*C5)*Assumptions!$C$47+Assumptions!$C$40)/D32)^(1/Assumptions!$C$45)-1 -> 0.17002641 | E40: =((($B40*C5)-E34-($B40*C5)*Assumptions!$C$47+Assumptions!$C$40)/E32)^(1/Assumptions!$C$45)-1 -> 0.18023766 | F40: =((($B40*C5)-F34-($B40*C5)*Assumptions!$C$47+Assumptions!$C$40)/F32)^(1/Assumptions!$C$45)-1 -> 0.19186069 | G40: =((($B40*C5)-G34-($B40*C5)*Assumptions!$C$47+Assumptions!$C$40)/G32)^(1/Assumptions!$C$45)-1 -> 0.20522672
B41: 11 | C41: =((($B41*C5)-C34-($B41*C5)*Assumptions!$C$47+Assumptions!$C$40)/C32)^(1/Assumptions!$C$45)-1 -> 0.18308803 | D41: =((($B41*C5)-D34-($B41*C5)*Assumptions!$C$47+Assumptions!$C$40)/D32)^(1/Assumptions!$C$45)-1 -> 0.19307523 | E41: =((($B41*C5)-E34-($B41*C5)*Assumptions!$C$47+Assumptions!$C$40)/E32)^(1/Assumptions!$C$45)-1 -> 0.20431434 | F41: =((($B41*C5)-F34-($B41*C5)*Assumptions!$C$47+Assumptions!$C$40)/F32)^(1/Assumptions!$C$45)-1 -> 0.21707094 | G41: =((($B41*C5)-G34-($B41*C5)*Assumptions!$C$47+Assumptions!$C$40)/G32)^(1/Assumptions!$C$45)-1 -> 0.23169567
B42: 12 | C42: =((($B42*C5)-C34-($B42*C5)*Assumptions!$C$47+Assumptions!$C$40)/C32)^(1/Assumptions!$C$45)-1 -> 0.2036602 | D42: =((($B42*C5)-D34-($B42*C5)*Assumptions!$C$47+Assumptions!$C$40)/D32)^(1/Assumptions!$C$45)-1 -> 0.21446937 | E42: =((($B42*C5)-E34-($B42*C5)*Assumptions!$C$47+Assumptions!$C$40)/E32)^(1/Assumptions!$C$45)-1 -> 0.22660669 | F42: =((($B42*C5)-F34-($B42*C5)*Assumptions!$C$47+Assumptions!$C$40)/F32)^(1/Assumptions!$C$45)-1 -> 0.24035044 | G42: =((($B42*C5)-G34-($B42*C5)*Assumptions!$C$47+Assumptions!$C$40)/G32)^(1/Assumptions!$C$45)-1 -> 0.25606741
B44: MOIC grid
B45: Exit multiple ↓ / Entry leverage → | C45: =C28 -> 3.5 | D45: =D28 -> 4 | E45: =E28 -> 4.5 | F45: =F28 -> 5 | G45: =G28 -> 5.5
B46: 8 | C46: =(($B46*C5)-C34-($B46*C5)*Assumptions!$C$47+Assumptions!$C$40)/C32 -> 1.6918959 | D46: =(($B46*C5)-D34-($B46*C5)*Assumptions!$C$47+Assumptions!$C$40)/D32 -> 1.7433908 | E46: =(($B46*C5)-E34-($B46*C5)*Assumptions!$C$47+Assumptions!$C$40)/E32 -> 1.8034398 | F46: =(($B46*C5)-F34-($B46*C5)*Assumptions!$C$47+Assumptions!$C$40)/F32 -> 1.8743674 | G46: =(($B46*C5)-G34-($B46*C5)*Assumptions!$C$47+Assumptions!$C$40)/G32 -> 1.9594241
B47: 9 | C47: =(($B47*C5)-C34-($B47*C5)*Assumptions!$C$47+Assumptions!$C$40)/C32 -> 1.9005472 | D47: =(($B47*C5)-D34-($B47*C5)*Assumptions!$C$47+Assumptions!$C$40)/D32 -> 1.9680432 | E47: =(($B47*C5)-E34-($B47*C5)*Assumptions!$C$47+Assumptions!$C$40)/E32 -> 2.0467512 | F47: =(($B47*C5)-F34-($B47*C5)*Assumptions!$C$47+Assumptions!$C$40)/F32 -> 2.1397181 | G47: =(($B47*C5)-G34-($B47*C5)*Assumptions!$C$47+Assumptions!$C$40)/G32 -> 2.2512044
B48: 10 | C48: =(($B48*C5)-C34-($B48*C5)*Assumptions!$C$47+Assumptions!$C$40)/C32 -> 2.1091985 | D48: =(($B48*C5)-D34-($B48*C5)*Assumptions!$C$47+Assumptions!$C$40)/D32 -> 2.1926955 | E48: =(($B48*C5)-E34-($B48*C5)*Assumptions!$C$47+Assumptions!$C$40)/E32 -> 2.2900625 | F48: =(($B48*C5)-F34-($B48*C5)*Assumptions!$C$47+Assumptions!$C$40)/F32 -> 2.4050687 | G48: =(($B48*C5)-G34-($B48*C5)*Assumptions!$C$47+Assumptions!$C$40)/G32 -> 2.5429848
...
